Error#2@2020-02-12 16h56.49.8175212
UnobservedTaskException
 ┌──────────────────────────■ Exception : AggregateException ■──────────────────────────
 | Message: A Task's exception(s) were not observed either by Waiting on the Task or accessing its Exception property. As a result, the unobserved exception was rethrown by the finalizer thread. (Unhandled exception on the default Task scheduler.)
 |  ┌──────────────────────────■ [Aggregated Exceptions] ■──────────────────────────
 |  |  ┌──────────────────────────■ Exception : Exception ■──────────────────────────
 |  |  | Message: Unhandled exception on the default Task scheduler.
 |  |  | Stack:    at Front.App.LoggerTestHostedService.<>c.<OnTime>b__10_0() in C:\Dev\CK\CK-Database-Projects\CK-Sample-MultiBinPath\Front.App\LoggerTestHostedService.cs:line 89
 |  |  |           at System.Threading.Tasks.Task`1.InnerInvoke()
 |  |  |           at System.Threading.Tasks.Task.<>c.<.cctor>b__274_0(Object obj)
 |  |  |           at System.Threading.ExecutionContext.RunFromThreadPoolDispatchLoop(Thread threadPoolThread, ExecutionContext executionContext, ContextCallback callback, Object state)
 |  |  |        --- End of stack trace from previous location where exception was thrown ---
 |  |  |           at System.Threading.Tasks.Task.ExecuteWithThreadLocal(Task& currentTaskSlot, Thread threadPoolThread)
 |  |  └─────────────────────────────────────────────────────────────────────────────
 |  └─────────────────────────────────────────────────────────────────────────
 └──────────────────────────────────────────────────────────────────────────────────────
